{"uuid": "7814a75f-b9dd-4e74-8b14-b0352afca8bd", "children": ["d42605d4-85ce-4cd9-8aa0-e1fb75f91661"], "befores": [{"name": "my_fixture", "status": "broken", "statusDetails": {"message": "pymysql.err.OperationalError: (1049, \"Unknown database 'data_operation_open_platform'\")\n", "trace": "  File \"C:\\Users\\shaoj\\AppData\\Local\\Programs\\Python\\Python311\\Lib\\site-packages\\pluggy\\_callers.py\", line 39, in _multicall\n    res = hook_impl.function(*args)\n          ^^^^^^^^^^^^^^^^^^^^^^^^^\n  File \"C:\\Users\\shaoj\\AppData\\Local\\Programs\\Python\\Python311\\Lib\\site-packages\\_pytest\\fixtures.py\", line 1130, in pytest_fixture_setup\n    result = call_fixture_func(fixturefunc, request, kwargs)\n             ^^^^^^^^^^^^^^^^^^^^^^^^^^^^^^^^^^^^^^^^^^^^^^^\n  File \"C:\\Users\\shaoj\\AppData\\Local\\Programs\\Python\\Python311\\Lib\\site-packages\\_pytest\\fixtures.py\", line 902, in call_fixture_func\n    fixture_result = next(generator)\n                     ^^^^^^^^^^^^^^^\n  File \"C:\\Users\\shaoj\\Desktop\\code\\pytest_testFile\\testcases\\conftest.py\", line 30, in my_fixture\n    mysql_client.execute(item.get(\"sqls\"))\n  File \"C:\\Users\\shaoj\\Desktop\\code\\pytest_testFile\\lib\\different_db\\mysqlclient_A.py\", line 38, in execute\n    with pymysql.connect(host=self.host,\n         ^^^^^^^^^^^^^^^^^^^^^^^^^^^^^^^\n  File \"C:\\Users\\shaoj\\AppData\\Local\\Programs\\Python\\Python311\\Lib\\site-packages\\pymysql\\connections.py\", line 352, in __init__\n    self.connect()\n  File \"C:\\Users\\shaoj\\AppData\\Local\\Programs\\Python\\Python311\\Lib\\site-packages\\pymysql\\connections.py\", line 636, in connect\n    self._request_authentication()\n  File \"C:\\Users\\shaoj\\AppData\\Local\\Programs\\Python\\Python311\\Lib\\site-packages\\pymysql\\connections.py\", line 911, in _request_authentication\n    auth_packet = self._read_packet()\n                  ^^^^^^^^^^^^^^^^^^^\n  File \"C:\\Users\\shaoj\\AppData\\Local\\Programs\\Python\\Python311\\Lib\\site-packages\\pymysql\\connections.py\", line 729, in _read_packet\n    packet.raise_for_error()\n  File \"C:\\Users\\shaoj\\AppData\\Local\\Programs\\Python\\Python311\\Lib\\site-packages\\pymysql\\protocol.py\", line 221, in raise_for_error\n    err.raise_mysql_exception(self._data)\n  File \"C:\\Users\\shaoj\\AppData\\Local\\Programs\\Python\\Python311\\Lib\\site-packages\\pymysql\\err.py\", line 143, in raise_mysql_exception\n    raise errorclass(errno, errval)\n"}, "start": 1686644934039, "stop": 1686644934064}], "start": 1686644934039, "stop": 1686644934251}