{"uuid": "7b357e74-30e1-4faa-9747-e329c69b653c", "children": ["e71f14a5-8d64-4d32-a356-452c976fc8a6"], "befores": [{"name": "my_fixture", "status": "passed", "start": 1686643275174, "stop": 1686643275174}], "afters": [{"name": "my_fixture::0", "status": "broken", "statusDetails": {"message": "pymysql.err.OperationalError: (1049, \"Unknown database 'data_operation_open_platform'\")\n", "trace": "  File \"C:\\Users\\shaoj\\AppData\\Local\\Programs\\Python\\Python311\\Lib\\site-packages\\allure_commons\\_allure.py\", line 221, in __call__\n    return self._fixture_function(*args, **kwargs)\n           ^^^^^^^^^^^^^^^^^^^^^^^^^^^^^^^^^^^^^^^\n  File \"C:\\Users\\shaoj\\AppData\\Local\\Programs\\Python\\Python311\\Lib\\site-packages\\_pytest\\fixtures.py\", line 918, in _teardown_yield_fixture\n    next(it)\n  File \"C:\\Users\\shaoj\\Desktop\\code\\pytest_testFile\\testcases\\conftest.py\", line 39, in my_fixture\n    mysql_client.execute(item.get(\"sqls\"))\n  File \"C:\\Users\\shaoj\\Desktop\\code\\pytest_testFile\\lib\\different_db\\mysqlclient_A.py\", line 38, in execute\n    with pymysql.connect(host=self.host,\n         ^^^^^^^^^^^^^^^^^^^^^^^^^^^^^^^\n  File \"C:\\Users\\shaoj\\AppData\\Local\\Programs\\Python\\Python311\\Lib\\site-packages\\pymysql\\connections.py\", line 352, in __init__\n    self.connect()\n  File \"C:\\Users\\shaoj\\AppData\\Local\\Programs\\Python\\Python311\\Lib\\site-packages\\pymysql\\connections.py\", line 636, in connect\n    self._request_authentication()\n  File \"C:\\Users\\shaoj\\AppData\\Local\\Programs\\Python\\Python311\\Lib\\site-packages\\pymysql\\connections.py\", line 911, in _request_authentication\n    auth_packet = self._read_packet()\n                  ^^^^^^^^^^^^^^^^^^^\n  File \"C:\\Users\\shaoj\\AppData\\Local\\Programs\\Python\\Python311\\Lib\\site-packages\\pymysql\\connections.py\", line 729, in _read_packet\n    packet.raise_for_error()\n  File \"C:\\Users\\shaoj\\AppData\\Local\\Programs\\Python\\Python311\\Lib\\site-packages\\pymysql\\protocol.py\", line 221, in raise_for_error\n    err.raise_mysql_exception(self._data)\n  File \"C:\\Users\\shaoj\\AppData\\Local\\Programs\\Python\\Python311\\Lib\\site-packages\\pymysql\\err.py\", line 143, in raise_mysql_exception\n    raise errorclass(errno, errval)\n"}, "start": 1686643275744, "stop": 1686643275764}], "start": 1686643275174, "stop": 1686643275764}